[?1049h[22;0;0t[1;24r(B[m[4l[?7h[?1l>Traceback (most recent call last):
  File "/usr/lib/python3.8/curses/__init__.py", line 89, in wrapper
    cbreak()
_curses.error: cbreak() returned ERR

During handling of the above exception, another exception occurred:

Traceback (most recent call last):
  File "register/ui.py", line 74, in <module>
    start()
  File "register/ui.py", line 68, in start
    curses.wrapper(main)
  File "/usr/lib/python3.8/curses/__init__.py", line 111, in wrapper
    nocbreak()
_curses.error: nocbreak() returned ERR
